<?xml version="1.0" ?>
<!-- =================================================================================== -->
<!-- |    This document was autogenerated by xacro from mini_model.xacro               | -->
<!-- |    EDITING THIS FILE BY HAND IS NOT RECOMMENDED                                 | -->
<!-- =================================================================================== -->
<robot name="mini_model">
  <material name="silver">
    <color rgba="0.700 0.700 0.700 1.000"/>
  </material>
  <!-- Sensor Materials -->
  <material name="camera_gray">
    <color rgba="0.5 0.5 0.5 1.0"/>
  </material>
  <material name="lidar_black">
    <color rgba="0.1 0.1 0.1 1.0"/>
  </material>
  <material name="imu_blue">
    <color rgba="0.0 0.3 0.8 1.0"/>
  </material>
  <material name="gps_green">
    <color rgba="0.0 0.8 0.3 1.0"/>
  </material>
  <gazebo reference="base_link">
    <material>Gazebo/Silver</material>
    <mu1>0.2</mu1>
    <mu2>0.2</mu2>
    <self_collide>true</self_collide>
    <gravity>true</gravity>
  </gazebo>
  <gazebo reference="component__8__1">
    <material>Gazebo/Silver</material>
    <mu1>2.0</mu1>
    <mu2>2.0</mu2>
    <slip1>0.0</slip1>
    <slip2>0.0</slip2>
    <self_collide>true</self_collide>
  </gazebo>
  <gazebo reference="component__1__1">
    <material>Gazebo/Silver</material>
    <mu1>2.0</mu1>
    <mu2>2.0</mu2>
    <slip1>0.0</slip1>
    <slip2>0.0</slip2>
    <self_collide>true</self_collide>
  </gazebo>
  <gazebo reference="component__2__1">
    <material>Gazebo/Silver</material>
    <mu1>2.0</mu1>
    <mu2>2.0</mu2>
    <slip1>0.0</slip1>
    <slip2>0.0</slip2>
    <self_collide>true</self_collide>
  </gazebo>
  <gazebo reference="component__3__1">
    <material>Gazebo/Silver</material>
    <mu1>2.0</mu1>
    <mu2>2.0</mu2>
    <slip1>0.0</slip1>
    <slip2>0.0</slip2>
    <self_collide>true</self_collide>
  </gazebo>
  <gazebo reference="component__4__1">
    <material>Gazebo/Silver</material>
    <mu1>2.0</mu1>
    <mu2>2.0</mu2>
    <slip1>0.0</slip1>
    <slip2>0.0</slip2>
    <self_collide>true</self_collide>
  </gazebo>
  <gazebo reference="component__5__1">
    <material>Gazebo/Silver</material>
    <mu1>2.0</mu1>
    <mu2>2.0</mu2>
    <slip1>0.0</slip1>
    <slip2>0.0</slip2>
    <self_collide>true</self_collide>
  </gazebo>
  <gazebo reference="component__6__1">
    <material>Gazebo/Silver</material>
    <mu1>2.0</mu1>
    <mu2>2.0</mu2>
    <slip1>0.0</slip1>
    <slip2>0.0</slip2>
    <self_collide>true</self_collide>
  </gazebo>
  <gazebo reference="component__7__1">
    <material>Gazebo/Silver</material>
    <mu1>2.0</mu1>
    <mu2>2.0</mu2>
    <slip1>0.0</slip1>
    <slip2>0.0</slip2>
    <self_collide>true</self_collide>
  </gazebo>
  <gazebo reference="component__9__1">
    <material>Gazebo/Silver</material>
    <mu1>2.0</mu1>
    <mu2>2.0</mu2>
    <slip1>0.0</slip1>
    <slip2>0.0</slip2>
    <self_collide>true</self_collide>
  </gazebo>
  <gazebo reference="component__11__1">
    <material>Gazebo/Silver</material>
    <mu1>2.0</mu1>
    <mu2>2.0</mu2>
    <slip1>0.0</slip1>
    <slip2>0.0</slip2>
    <self_collide>true</self_collide>
  </gazebo>
  <gazebo reference="component__10__1">
    <material>Gazebo/Silver</material>
    <mu1>2.0</mu1>
    <mu2>2.0</mu2>
    <slip1>0.0</slip1>
    <slip2>0.0</slip2>
    <self_collide>true</self_collide>
  </gazebo>
  <gazebo reference="component__14__1">
    <material>Gazebo/Silver</material>
    <mu1>2.0</mu1>
    <mu2>2.0</mu2>
    <slip1>0.0</slip1>
    <slip2>0.0</slip2>
    <self_collide>true</self_collide>
  </gazebo>
  <gazebo reference="component__13__1">
    <material>Gazebo/Silver</material>
    <mu1>2.0</mu1>
    <mu2>2.0</mu2>
    <slip1>0.0</slip1>
    <slip2>0.0</slip2>
    <self_collide>true</self_collide>
  </gazebo>
  <gazebo reference="component__12__1">
    <material>Gazebo/Silver</material>
    <mu1>2.0</mu1>
    <mu2>2.0</mu2>
    <slip1>0.0</slip1>
    <slip2>0.0</slip2>
    <self_collide>true</self_collide>
  </gazebo>
  <!--
  AUTONOMOUS NAVIGATION SENSORS FOR ROCKER-BOGIE ROVER
  
  This file defines all sensors needed for autonomous navigation:
  - Intel RealSense D435i (RGB-D Camera)
  - Hokuyo UST-10LX (2D LiDAR - 270° wide angle)
  - Standalone IMU (9-DOF)
  - RTK-GPS (High-precision positioning)
  
  All sensors are attached to base_link with appropriate positioning
  for optimal coverage and minimal interference.
-->
  <!--
  GAZEBO IGNITION FORTRESS SENSOR PLUGINS
  
  This file contains all Gazebo sensor plugin configurations for:
  - Intel RealSense D435i (RGBD Camera)
  - Hokuyo UST-10LX (2D LiDAR)
  - IMU Sensor
  - RTK-GPS Sensor
  
  Note: Ignition Fortress uses the gz-sim-sensors-system plugin
  for all sensor types. Individual sensor configurations are
  embedded within the <gazebo> tags.
-->
  <!-- ============================================ -->
  <!-- INTEL REALSENSE D435i RGBD CAMERA            -->
  <!-- ============================================ -->
  <gazebo reference="camera_link">
    <!-- RGBD Camera Sensor -->
    <sensor name="realsense_d435i" type="rgbd_camera">
      <always_on>1</always_on>
      <update_rate>30.0</update_rate>
      <topic>camera</topic>
      <gz_frame_id>camera_optical_frame</gz_frame_id>
      <enable_metrics>false</enable_metrics>
      <camera>
        <!-- D435i RGB Stream: 1920x1080 @ 30fps -->
        <!-- Horizontal FOV: 90° = 1.5708 radians -->
        <horizontal_fov>1.5708</horizontal_fov>
        <image>
          <width>1280</width>
          <height>720</height>
          <format>R8G8B8</format>
        </image>
        <clip>
          <near>0.1</near>
          <far>100.0</far>
        </clip>
        <distortion>
          <k1>0.0</k1>
          <k2>0.0</k2>
          <k3>0.0</k3>
          <p1>0.0</p1>
          <p2>0.0</p2>
          <center>0.5 0.5</center>
        </distortion>
        <!-- Depth camera specific settings -->
        <depth_camera>
          <clip>
            <near>0.3</near>
            <far>10.0</far>
          </clip>
        </depth_camera>
        <!-- Image noise for realism -->
        <noise>
          <type>gaussian</type>
          <mean>0.0</mean>
          <stddev>0.007</stddev>
        </noise>
      </camera>
      <visualize>true</visualize>
    </sensor>
  </gazebo>
  <!-- ============================================ -->
  <!-- HOKUYO UST-10LX 2D LIDAR                     -->
  <!-- ============================================ -->
  <!-- Specifications:
     - Range: 0.06m to 10m (60mm to 10,000mm)
     - Angular Resolution: 0.25° (1081 samples over 270°)
     - Scan Rate: 40 Hz
     - Field of View: 270° (-135° to +135°)
     - Accuracy: ±40mm at 1-10m range
-->
  <!-- ============================================ -->
  <gazebo reference="laser_link">
    <!-- GPU LiDAR Sensor (Required for Ignition Fortress) -->
    <sensor name="hokuyo_ust10lx" type="gpu_lidar">
      <!-- Always active for continuous scanning -->
      <always_on>true</always_on>
      <!-- 40 Hz update rate (Hokuyo UST-10LX specification) -->
      <update_rate>40.0</update_rate>
      <!-- Ignition topic (bridged to ROS /scan by ros_gz_bridge) -->
      <topic>scan</topic>
      <!-- Frame ID for ROS integration -->
      <gz_frame_id>laser_link</gz_frame_id>
      <!-- VISUALIZE RAYS IN GAZEBO SIMULATION (blue rays) -->
      <visualize>true</visualize>
      <!-- LiDAR Configuration using <ray> for proper visualization -->
      <ray>
        <scan>
          <!-- HORIZONTAL SCAN PLANE -->
          <horizontal>
            <!-- 270° FOV: -135° to +135° -->
            <!-- 0.25° angular resolution = 1081 samples -->
            <samples>1081</samples>
            <!-- Resolution: 1.0 = no subsampling -->
            <resolution>1</resolution>
            <!-- Scan angles in radians -->
            <min_angle>-2.35619449</min_angle>
            <max_angle>2.35619449</max_angle>
          </horizontal>
          <!-- VERTICAL (2D LiDAR = single horizontal plane) -->
          <vertical>
            <samples>1</samples>
            <resolution>1</resolution>
            <min_angle>0</min_angle>
            <max_angle>0</max_angle>
          </vertical>
        </scan>
        <!-- RANGE CONFIGURATION -->
        <range>
          <!-- Minimum range: 60mm (Hokuyo UST-10LX spec) -->
          <min>0.06</min>
          <!-- Maximum range: 10m (Hokuyo UST-10LX spec) -->
          <max>10.0</max>
          <!-- Range resolution: 10mm -->
          <resolution>0.01</resolution>
        </range>
        <!-- GAUSSIAN NOISE (realistic ±40mm at 1-10m) -->
        <noise>
          <type>gaussian</type>
          <mean>0.0</mean>
          <stddev>0.04</stddev>
        </noise>
      </ray>
    </sensor>
  </gazebo>
  <!-- ============================================ -->
  <!-- STANDALONE IMU SENSOR                        -->
  <!-- ============================================ -->
  <gazebo reference="imu_link">
    <sensor name="imu_sensor" type="imu">
      <always_on>1</always_on>
      <update_rate>100.0</update_rate>
      <topic>imu</topic>
      <enable_metrics>false</enable_metrics>
      <imu>
        <!-- Angular Velocity (Gyroscope) -->
        <angular_velocity>
          <x>
            <noise type="gaussian">
              <mean>0.0</mean>
              <stddev>2e-4</stddev>
              <bias_mean>0.0000075</bias_mean>
              <bias_stddev>0.0000008</bias_stddev>
            </noise>
          </x>
          <y>
            <noise type="gaussian">
              <mean>0.0</mean>
              <stddev>2e-4</stddev>
              <bias_mean>0.0000075</bias_mean>
              <bias_stddev>0.0000008</bias_stddev>
            </noise>
          </y>
          <z>
            <noise type="gaussian">
              <mean>0.0</mean>
              <stddev>2e-4</stddev>
              <bias_mean>0.0000075</bias_mean>
              <bias_stddev>0.0000008</bias_stddev>
            </noise>
          </z>
        </angular_velocity>
        <!-- Linear Acceleration (Accelerometer) -->
        <linear_acceleration>
          <x>
            <noise type="gaussian">
              <mean>0.0</mean>
              <stddev>1.7e-2</stddev>
              <bias_mean>0.1</bias_mean>
              <bias_stddev>0.001</bias_stddev>
            </noise>
          </x>
          <y>
            <noise type="gaussian">
              <mean>0.0</mean>
              <stddev>1.7e-2</stddev>
              <bias_mean>0.1</bias_mean>
              <bias_stddev>0.001</bias_stddev>
            </noise>
          </y>
          <z>
            <noise type="gaussian">
              <mean>0.0</mean>
              <stddev>1.7e-2</stddev>
              <bias_mean>0.1</bias_mean>
              <bias_stddev>0.001</bias_stddev>
            </noise>
          </z>
        </linear_acceleration>
      </imu>
      <visualize>false</visualize>
    </sensor>
  </gazebo>
  <!-- ============================================ -->
  <!-- NAVSAT GPS SENSOR (Ignition Fortress)       -->
  <!-- ============================================ -->
  <!-- For Ignition Fortress, NavSat sensor is defined here -->
  <!-- System plugin is in world file (gz-sim-navsat-system) -->
  <!-- No ROS plugin needed - ros_gz_bridge handles ROS 2 -->
  <!-- ============================================ -->
  <gazebo reference="gps_link">
    <sensor name="gps_sensor" type="navsat">
      <!-- Always on for continuous GPS readings -->
      <always_on>true</always_on>
      <!-- Update rate: 10 Hz (standard GPS update rate) -->
      <update_rate>10.0</update_rate>
      <!-- Ignition topic (bridged to ROS /gps/fix by ros_gz_bridge) -->
      <topic>gps</topic>
      <!-- NavSat-specific configuration -->
      <!-- NOTE: Noise values are in DEGREES for position, m/s for velocity -->
      <!-- 1 degree latitude ≈ 111,320 meters, so: -->
      <!-- 0.02m / 111320 ≈ 1.8e-7 degrees for 2cm accuracy -->
      <!-- 0.03m / 111320 ≈ 2.7e-7 degrees for 3cm accuracy -->
      <navsat>
        <!-- Position sensing with noise for realism -->
        <position_sensing>
          <horizontal>
            <!-- RTK-GPS horizontal accuracy: ±2cm = 1.8e-7 degrees -->
            <noise type="gaussian">
              <mean>0.0</mean>
              <stddev>0.00000002</stddev>
            </noise>
          </horizontal>
          <vertical>
            <!-- RTK-GPS vertical accuracy: ±3cm (in meters for altitude) -->
            <noise type="gaussian">
              <mean>0.0</mean>
              <stddev>0.03</stddev>
            </noise>
          </vertical>
        </position_sensing>
        <!-- Velocity sensing with noise (in m/s) -->
        <velocity_sensing>
          <horizontal>
            <!-- Velocity accuracy: ±0.01 m/s -->
            <noise type="gaussian">
              <mean>0.0</mean>
              <stddev>0.001</stddev>
            </noise>
          </horizontal>
          <vertical>
            <noise type="gaussian">
              <mean>0.0</mean>
              <stddev>0.003</stddev>
            </noise>
          </vertical>
        </velocity_sensing>
      </navsat>
      <!-- Don't visualize GPS sensor in GUI -->
      <visualize>false</visualize>
    </sensor>
  </gazebo>
  <!-- ============================================ -->
  <!-- POSE PUBLISHER PLUGIN (for NavSat)          -->
  <!-- ============================================ -->
  <!-- Publishes model pose for NavSat to convert to GPS coordinates -->
  <gazebo>
    <plugin filename="gz-sim-pose-publisher-system" name="gz::sim::systems::PosePublisher">
      <publish_link_pose>true</publish_link_pose>
      <publish_sensor_pose>true</publish_sensor_pose>
      <publish_collision_pose>false</publish_collision_pose>
      <publish_visual_pose>false</publish_visual_pose>
      <publish_nested_model_pose>true</publish_nested_model_pose>
      <update_frequency>10</update_frequency>
    </plugin>
  </gazebo>
  <link name="base_link">
    <inertial>
      <origin rpy="0 0 0" xyz="0.0 0.0 0.0"/>
      <mass value="628.0"/>
      <inertia ixx="15.176667" ixy="0.0" ixz="0.0" iyy="46.576667" iyz="0.0" izz="35.586667"/>
    </inertial>
    <visual>
      <origin rpy="0 0 0" xyz="0 0 0"/>
      <geometry>
        <mesh filename="package://mini_model_description/meshes/base_link.stl" scale="0.001 0.001 0.001"/>
      </geometry>
      <material name="silver"/>
    </visual>
    <collision>
      <origin rpy="0 0 0" xyz="0 0 0"/>
      <geometry>
        <mesh filename="package://mini_model_description/meshes/base_link.stl" scale="0.001 0.001 0.001"/>
      </geometry>
    </collision>
  </link>
  <link name="component__8__1">
    <inertial>
      <origin rpy="0 0 0" xyz="0.1134912204829699 -0.05030777295699913 0.029954747066772536"/>
      <mass value="5.449702499230522"/>
      <inertia ixx="0.013083" ixy="0.036122" ixz="-2.8e-05" iyy="0.270388" iyz="1.2e-05" izz="0.283097"/>
    </inertial>
    <visual>
      <origin rpy="0 0 0" xyz="-0.0 -0.0 -0.25"/>
      <geometry>
        <mesh filename="package://mini_model_description/meshes/component__8__1.stl" scale="0.001 0.001 0.001"/>
      </geometry>
      <material name="silver"/>
    </visual>
    <collision>
      <origin rpy="0 0 0" xyz="-0.0 -0.0 -0.25"/>
      <geometry>
        <mesh filename="package://mini_model_description/meshes/component__8__1.stl" scale="0.001 0.001 0.001"/>
      </geometry>
    </collision>
  </link>
  <link name="component__1__1">
    <inertial>
      <origin rpy="0 0 0" xyz="0.014564589996318489 -0.07826500014971428 0.010000000000000009"/>
      <mass value="3.923134667678356"/>
      <inertia ixx="0.016852" ixy="0.027919" ixz="0.0" iyy="0.089659" iyz="-0.0" izz="0.106249"/>
    </inertial>
    <visual>
      <origin rpy="0 0 0" xyz="0.25 0.066987 -0.29"/>
      <geometry>
        <mesh filename="package://mini_model_description/meshes/component__1__1.stl" scale="0.001 0.001 0.001"/>
      </geometry>
      <material name="silver"/>
    </visual>
    <collision>
      <origin rpy="0 0 0" xyz="0.25 0.066987 -0.29"/>
      <geometry>
        <mesh filename="package://mini_model_description/meshes/component__1__1.stl" scale="0.001 0.001 0.001"/>
      </geometry>
    </collision>
  </link>
  <link name="component__2__1">
    <inertial>
      <origin rpy="0 0 0" xyz="8.326672684688674e-16 -0.07524710992668415 0.0"/>
      <mass value="0.9442697396325618"/>
      <inertia ixx="0.00182" ixy="0.0" ixz="-0.0" iyy="0.000154" iyz="-0.0" izz="0.001911"/>
    </inertial>
    <visual>
      <origin rpy="0 0 0" xyz="0.5 0.149321 -0.3"/>
      <geometry>
        <mesh filename="package://mini_model_description/meshes/component__2__1.stl" scale="0.001 0.001 0.001"/>
      </geometry>
      <material name="silver"/>
    </visual>
    <collision>
      <origin rpy="0 0 0" xyz="0.5 0.149321 -0.3"/>
      <geometry>
        <mesh filename="package://mini_model_description/meshes/component__2__1.stl" scale="0.001 0.001 0.001"/>
      </geometry>
    </collision>
  </link>
  <link name="component__3__1">
    <inertial>
      <origin rpy="0 0 0" xyz="-1.3322676295501878e-15 -0.07524710992668368 0.0"/>
      <mass value="0.9442697396325564"/>
      <inertia ixx="0.00182" ixy="0.0" ixz="0.0" iyy="0.000154" iyz="0.0" izz="0.001911"/>
    </inertial>
    <visual>
      <origin rpy="0 0 0" xyz="-0.5 0.149321 -0.28"/>
      <geometry>
        <mesh filename="package://mini_model_description/meshes/component__3__1.stl" scale="0.001 0.001 0.001"/>
      </geometry>
      <material name="silver"/>
    </visual>
    <collision>
      <origin rpy="0 0 0" xyz="-0.5 0.149321 -0.28"/>
      <geometry>
        <mesh filename="package://mini_model_description/meshes/component__3__1.stl" scale="0.001 0.001 0.001"/>
      </geometry>
    </collision>
  </link>
  <link name="component__4__1">
    <inertial>
      <origin rpy="0 0 0" xyz="8.326672684688674e-16 4.037844391069356e-07 0.050132954214166414"/>
      <mass value="24.72411519366146"/>
      <inertia ixx="0.082388" ixy="0.0" ixz="0.0" iyy="0.082388" iyz="0.0" izz="0.123329"/>
    </inertial>
    <visual>
      <origin rpy="0 0 0" xyz="0.5 0.283975 -0.31"/>
      <geometry>
        <mesh filename="package://mini_model_description/meshes/component__4__1.stl" scale="0.001 0.001 0.001"/>
      </geometry>
      <material name="silver"/>
    </visual>
    <collision>
      <origin rpy="0 0 0" xyz="0.5 0.283975 -0.31"/>
      <geometry>
        <mesh filename="package://mini_model_description/meshes/component__4__1.stl" scale="0.001 0.001 0.001"/>
      </geometry>
    </collision>
  </link>
  <link name="component__5__1">
    <inertial>
      <origin rpy="0 0 0" xyz="-3.003187247395517e-16 4.0378443955102483e-07 0.050132954214166414"/>
      <mass value="24.724115193661465"/>
      <inertia ixx="0.082388" ixy="0.0" ixz="0.0" iyy="0.082388" iyz="0.0" izz="0.123329"/>
    </inertial>
    <visual>
      <origin rpy="0 0 0" xyz="0.0 0.283975 -0.31"/>
      <geometry>
        <mesh filename="package://mini_model_description/meshes/component__5__1.stl" scale="0.001 0.001 0.001"/>
      </geometry>
      <material name="silver"/>
    </visual>
    <collision>
      <origin rpy="0 0 0" xyz="0.0 0.283975 -0.31"/>
      <geometry>
        <mesh filename="package://mini_model_description/meshes/component__5__1.stl" scale="0.001 0.001 0.001"/>
      </geometry>
    </collision>
  </link>
  <link name="component__6__1">
    <inertial>
      <origin rpy="0 0 0" xyz="-1.4432899320127035e-15 4.037844399396029e-07 0.05013295421416647"/>
      <mass value="24.72411519366146"/>
      <inertia ixx="0.082388" ixy="0.0" ixz="0.0" iyy="0.082388" iyz="-0.0" izz="0.123329"/>
    </inertial>
    <visual>
      <origin rpy="0 0 0" xyz="-0.5 0.283975 -0.29"/>
      <geometry>
        <mesh filename="package://mini_model_description/meshes/component__6__1.stl" scale="0.001 0.001 0.001"/>
      </geometry>
      <material name="silver"/>
    </visual>
    <collision>
      <origin rpy="0 0 0" xyz="-0.5 0.283975 -0.29"/>
      <geometry>
        <mesh filename="package://mini_model_description/meshes/component__6__1.stl" scale="0.001 0.001 0.001"/>
      </geometry>
    </collision>
  </link>
  <link name="component__7__1">
    <inertial>
      <origin rpy="0 0 0" xyz="0.11349122048296997 -0.0503077729569992 -0.02995474706677259"/>
      <mass value="5.449702499230521"/>
      <inertia ixx="0.013083" ixy="0.036122" ixz="2.8e-05" iyy="0.270388" iyz="-1.2e-05" izz="0.283097"/>
    </inertial>
    <visual>
      <origin rpy="0 0 0" xyz="-0.0 -0.0 0.25"/>
      <geometry>
        <mesh filename="package://mini_model_description/meshes/component__7__1.stl" scale="0.001 0.001 0.001"/>
      </geometry>
      <material name="silver"/>
    </visual>
    <collision>
      <origin rpy="0 0 0" xyz="-0.0 -0.0 0.25"/>
      <geometry>
        <mesh filename="package://mini_model_description/meshes/component__7__1.stl" scale="0.001 0.001 0.001"/>
      </geometry>
    </collision>
  </link>
  <link name="component__9__1">
    <inertial>
      <origin rpy="0 0 0" xyz="0.014564589996318461 -0.07826500014971409 -0.010000000000000064"/>
      <mass value="3.9231346676783514"/>
      <inertia ixx="0.016852" ixy="0.027919" ixz="0.0" iyy="0.089659" iyz="0.0" izz="0.106249"/>
    </inertial>
    <visual>
      <origin rpy="0 0 0" xyz="0.25 0.066987 0.29"/>
      <geometry>
        <mesh filename="package://mini_model_description/meshes/component__9__1.stl" scale="0.001 0.001 0.001"/>
      </geometry>
      <material name="silver"/>
    </visual>
    <collision>
      <origin rpy="0 0 0" xyz="0.25 0.066987 0.29"/>
      <geometry>
        <mesh filename="package://mini_model_description/meshes/component__9__1.stl" scale="0.001 0.001 0.001"/>
      </geometry>
    </collision>
  </link>
  <link name="component__11__1">
    <inertial>
      <origin rpy="0 0 0" xyz="-1.3322676295501878e-15 -0.07524710992668368 0.0"/>
      <mass value="0.9442697396325564"/>
      <inertia ixx="0.00182" ixy="0.0" ixz="-0.0" iyy="0.000154" iyz="0.0" izz="0.001911"/>
    </inertial>
    <visual>
      <origin rpy="0 0 0" xyz="-0.5 0.149321 0.28"/>
      <geometry>
        <mesh filename="package://mini_model_description/meshes/component__11__1.stl" scale="0.001 0.001 0.001"/>
      </geometry>
      <material name="silver"/>
    </visual>
    <collision>
      <origin rpy="0 0 0" xyz="-0.5 0.149321 0.28"/>
      <geometry>
        <mesh filename="package://mini_model_description/meshes/component__11__1.stl" scale="0.001 0.001 0.001"/>
      </geometry>
    </collision>
  </link>
  <link name="component__10__1">
    <inertial>
      <origin rpy="0 0 0" xyz="8.326672684688674e-16 -0.07524710992668415 0.0"/>
      <mass value="0.9442697396325618"/>
      <inertia ixx="0.00182" ixy="0.0" ixz="0.0" iyy="0.000154" iyz="-0.0" izz="0.001911"/>
    </inertial>
    <visual>
      <origin rpy="0 0 0" xyz="0.5 0.149321 0.3"/>
      <geometry>
        <mesh filename="package://mini_model_description/meshes/component__10__1.stl" scale="0.001 0.001 0.001"/>
      </geometry>
      <material name="silver"/>
    </visual>
    <collision>
      <origin rpy="0 0 0" xyz="0.5 0.149321 0.3"/>
      <geometry>
        <mesh filename="package://mini_model_description/meshes/component__10__1.stl" scale="0.001 0.001 0.001"/>
      </geometry>
    </collision>
  </link>
  <link name="component__14__1">
    <inertial>
      <origin rpy="0 0 0" xyz="6.772360450213455e-15 4.037844399396029e-07 -0.05013295421416647"/>
      <mass value="24.72411519366147"/>
      <inertia ixx="0.082388" ixy="0.0" ixz="0.0" iyy="0.082388" iyz="0.0" izz="0.123329"/>
    </inertial>
    <visual>
      <origin rpy="0 0 0" xyz="-0.5 0.283975 0.29"/>
      <geometry>
        <mesh filename="package://mini_model_description/meshes/component__14__1.stl" scale="0.001 0.001 0.001"/>
      </geometry>
      <material name="silver"/>
    </visual>
    <collision>
      <origin rpy="0 0 0" xyz="-0.5 0.283975 0.29"/>
      <geometry>
        <mesh filename="package://mini_model_description/meshes/component__14__1.stl" scale="0.001 0.001 0.001"/>
      </geometry>
    </collision>
  </link>
  <link name="component__13__1">
    <inertial>
      <origin rpy="0 0 0" xyz="7.866040444139796e-15 4.03784439606536e-07 -0.050132954214166414"/>
      <mass value="24.724115193661465"/>
      <inertia ixx="0.082388" ixy="0.0" ixz="0.0" iyy="0.082388" iyz="-0.0" izz="0.123329"/>
    </inertial>
    <visual>
      <origin rpy="0 0 0" xyz="0.0 0.283975 0.31"/>
      <geometry>
        <mesh filename="package://mini_model_description/meshes/component__13__1.stl" scale="0.001 0.001 0.001"/>
      </geometry>
      <material name="silver"/>
    </visual>
    <collision>
      <origin rpy="0 0 0" xyz="0.0 0.283975 0.31"/>
      <geometry>
        <mesh filename="package://mini_model_description/meshes/component__13__1.stl" scale="0.001 0.001 0.001"/>
      </geometry>
    </collision>
  </link>
  <link name="component__12__1">
    <inertial>
      <origin rpy="0 0 0" xyz="9.048317650695026e-15 4.0378443905142447e-07 -0.050132954214166525"/>
      <mass value="24.72411519366147"/>
      <inertia ixx="0.082388" ixy="0.0" ixz="0.0" iyy="0.082388" iyz="0.0" izz="0.123329"/>
    </inertial>
    <visual>
      <origin rpy="0 0 0" xyz="0.5 0.283975 0.31"/>
      <geometry>
        <mesh filename="package://mini_model_description/meshes/component__12__1.stl" scale="0.001 0.001 0.001"/>
      </geometry>
      <material name="silver"/>
    </visual>
    <collision>
      <origin rpy="0 0 0" xyz="0.5 0.283975 0.31"/>
      <geometry>
        <mesh filename="package://mini_model_description/meshes/component__12__1.stl" scale="0.001 0.001 0.001"/>
      </geometry>
    </collision>
  </link>
  <joint name="Revolute 25" type="revolute">
    <origin rpy="0 0 0" xyz="0.0 0.0 0.25"/>
    <parent link="base_link"/>
    <child link="component__8__1"/>
    <axis xyz="0.0 0.0 1.0"/>
    <limit effort="100" lower="-0.523599" upper="0.523599" velocity="100"/>
  </joint>
  <joint name="Revolute 26" type="revolute">
    <origin rpy="0 0 0" xyz="-0.25 -0.066987 0.04"/>
    <parent link="component__8__1"/>
    <child link="component__1__1"/>
    <axis xyz="0.0 0.0 1.0"/>
    <limit effort="100" lower="-0.523599" upper="0.523599" velocity="100"/>
  </joint>
  <joint name="Revolute 27" type="revolute">
    <origin rpy="0 0 0" xyz="-0.25 -0.082334 0.01"/>
    <parent link="component__1__1"/>
    <child link="component__2__1"/>
    <axis xyz="0.0 -1.0 0.0"/>
    <limit effort="500" lower="-0.785398" upper="0.785398" velocity="100"/>
    <dynamics damping="50.0" friction="3.5"/>
  </joint>
  <joint name="Revolute 28" type="revolute">
    <origin rpy="0 0 0" xyz="0.5 -0.149321 0.03"/>
    <parent link="component__8__1"/>
    <child link="component__3__1"/>
    <axis xyz="0.0 -1.0 0.0"/>
    <limit effort="500" lower="-0.785398" upper="0.785398" velocity="100"/>
    <dynamics damping="50.0" friction="3.5"/>
  </joint>
  <joint name="Revolute 29" type="continuous">
    <origin rpy="0 0 0" xyz="0.0 -0.134654 0.01"/>
    <parent link="component__2__1"/>
    <child link="component__4__1"/>
    <axis xyz="0.0 0.0 1.0"/>
  </joint>
  <joint name="Revolute 30" type="continuous">
    <origin rpy="0 0 0" xyz="0.25 -0.216988 0.02"/>
    <parent link="component__1__1"/>
    <child link="component__5__1"/>
    <axis xyz="0.0 0.0 1.0"/>
  </joint>
  <joint name="Revolute 31" type="continuous">
    <origin rpy="0 0 0" xyz="0.0 -0.134654 0.01"/>
    <parent link="component__3__1"/>
    <child link="component__6__1"/>
    <axis xyz="0.0 0.0 1.0"/>
  </joint>
  <joint name="Revolute 32" type="revolute">
    <origin rpy="0 0 0" xyz="0.0 0.0 -0.25"/>
    <parent link="base_link"/>
    <child link="component__7__1"/>
    <axis xyz="0.0 0.0 -1.0"/>
    <limit effort="100" lower="-0.523599" upper="0.523599" velocity="100"/>
  </joint>
  <joint name="Revolute 33" type="revolute">
    <origin rpy="0 0 0" xyz="-0.25 -0.066987 -0.04"/>
    <parent link="component__7__1"/>
    <child link="component__9__1"/>
    <axis xyz="0.0 0.0 -1.0"/>
    <limit effort="100" lower="-0.523599" upper="0.523599" velocity="100"/>
  </joint>
  <joint name="Revolute 34" type="revolute">
    <origin rpy="0 0 0" xyz="0.5 -0.149321 -0.03"/>
    <parent link="component__7__1"/>
    <child link="component__11__1"/>
    <axis xyz="0.0 -1.0 0.0"/>
    <limit effort="500" lower="-0.785398" upper="0.785398" velocity="100"/>
    <dynamics damping="50.0" friction="3.5"/>
  </joint>
  <joint name="Revolute 35" type="revolute">
    <origin rpy="0 0 0" xyz="-0.25 -0.082334 -0.01"/>
    <parent link="component__9__1"/>
    <child link="component__10__1"/>
    <axis xyz="0.0 -1.0 0.0"/>
    <limit effort="500" lower="-0.785398" upper="0.785398" velocity="100"/>
    <dynamics damping="50.0" friction="3.5"/>
  </joint>
  <joint name="Revolute 36" type="continuous">
    <origin rpy="0 0 0" xyz="0.0 -0.134654 -0.01"/>
    <parent link="component__11__1"/>
    <child link="component__14__1"/>
    <axis xyz="0.0 0.0 -1.0"/>
  </joint>
  <joint name="Revolute 37" type="continuous">
    <origin rpy="0 0 0" xyz="0.25 -0.216988 -0.02"/>
    <parent link="component__9__1"/>
    <child link="component__13__1"/>
    <axis xyz="0.0 0.0 -1.0"/>
  </joint>
  <joint name="Revolute 38" type="continuous">
    <origin rpy="0 0 0" xyz="0.0 -0.134654 -0.01"/>
    <parent link="component__10__1"/>
    <child link="component__12__1"/>
    <axis xyz="0.0 0.0 -1.0"/>
  </joint>
  <!-- ROS 2 Control Hardware Interface -->
  <ros2_control name="GazeboSimSystem" type="system">
    <hardware>
      <plugin>gz_ros2_control/GazeboSimSystem</plugin>
    </hardware>
    <!-- PASSIVE SUSPENSION JOINTS (State Interface Only) -->
    <!-- Right Differential Joint -->
    <joint name="Revolute 25">
      <command_interface name="position">
        <param name="min">-0.523599</param>
        <param name="max">0.523599</param>
      </command_interface>
      <state_interface name="position"/>
      <state_interface name="velocity"/>
    </joint>
    <!-- Right Bogie Pivot Joint -->
    <joint name="Revolute 26">
      <command_interface name="position">
        <param name="min">-0.523599</param>
        <param name="max">0.523599</param>
      </command_interface>
      <state_interface name="position"/>
      <state_interface name="velocity"/>
    </joint>
    <!-- Left Differential Joint -->
    <joint name="Revolute 32">
      <command_interface name="position">
        <param name="min">-0.523599</param>
        <param name="max">0.523599</param>
      </command_interface>
      <state_interface name="position"/>
      <state_interface name="velocity"/>
    </joint>
    <!-- Left Bogie Pivot Joint -->
    <joint name="Revolute 33">
      <command_interface name="position">
        <param name="min">-0.523599</param>
        <param name="max">0.523599</param>
      </command_interface>
      <state_interface name="position"/>
      <state_interface name="velocity"/>
    </joint>
    <!-- STEERING JOINTS (Position Command Interface) -->
    <!-- Rear Right Wheel Steering -->
    <joint name="Revolute 27">
      <command_interface name="position">
        <param name="min">-0.785398</param>
        <param name="max">0.785398</param>
        <param name="p">80.0</param>
        <param name="i">1.5</param>
        <param name="d">10.0</param>
      </command_interface>
      <state_interface name="position"/>
      <state_interface name="velocity"/>
    </joint>
    <!-- Front Right Wheel Steering -->
    <joint name="Revolute 28">
      <command_interface name="position">
        <param name="min">-0.785398</param>
        <param name="max">0.785398</param>
        <param name="p">80.0</param>
        <param name="i">1.5</param>
        <param name="d">10.0</param>
      </command_interface>
      <state_interface name="position"/>
      <state_interface name="velocity"/>
    </joint>
    <!-- Front Left Wheel Steering -->
    <joint name="Revolute 34">
      <command_interface name="position">
        <param name="min">-0.785398</param>
        <param name="max">0.785398</param>
        <param name="p">80.0</param>
        <param name="i">1.5</param>
        <param name="d">10.0</param>
      </command_interface>
      <state_interface name="position"/>
      <state_interface name="velocity"/>
    </joint>
    <!-- Rear Left Wheel Steering -->
    <joint name="Revolute 35">
      <command_interface name="position">
        <param name="min">-0.785398</param>
        <param name="max">0.785398</param>
        <param name="p">80.0</param>
        <param name="i">1.5</param>
        <param name="d">10.0</param>
      </command_interface>
      <state_interface name="position"/>
      <state_interface name="velocity"/>
    </joint>
    <!-- DRIVE JOINTS (Velocity Command Interface) -->
    <!-- Rear Right Wheel Drive -->
    <joint name="Revolute 29">
      <command_interface name="velocity">
        <param name="min">-50.0</param>
        <param name="max">50.0</param>
      </command_interface>
      <state_interface name="position"/>
      <state_interface name="velocity"/>
    </joint>
    <!-- Middle Right Wheel Drive -->
    <joint name="Revolute 30">
      <command_interface name="velocity">
        <param name="min">-50.0</param>
        <param name="max">50.0</param>
      </command_interface>
      <state_interface name="position"/>
      <state_interface name="velocity"/>
    </joint>
    <!-- Front Right Wheel Drive -->
    <joint name="Revolute 31">
      <command_interface name="velocity">
        <param name="min">-50.0</param>
        <param name="max">50.0</param>
      </command_interface>
      <state_interface name="position"/>
      <state_interface name="velocity"/>
    </joint>
    <!-- Front Left Wheel Drive -->
    <joint name="Revolute 36">
      <command_interface name="velocity">
        <param name="min">-50.0</param>
        <param name="max">50.0</param>
      </command_interface>
      <state_interface name="position"/>
      <state_interface name="velocity"/>
    </joint>
    <!-- Middle Left Wheel Drive -->
    <joint name="Revolute 37">
      <command_interface name="velocity">
        <param name="min">-50.0</param>
        <param name="max">50.0</param>
      </command_interface>
      <state_interface name="position"/>
      <state_interface name="velocity"/>
    </joint>
    <!-- Rear Left Wheel Drive -->
    <joint name="Revolute 38">
      <command_interface name="velocity">
        <param name="min">-50.0</param>
        <param name="max">50.0</param>
      </command_interface>
      <state_interface name="position"/>
      <state_interface name="velocity"/>
    </joint>
  </ros2_control>
  <!-- Gazebo ROS 2 Control Plugin -->
  <gazebo>
    <plugin filename="gz_ros2_control-system" name="gz_ros2_control::GazeboSimROS2ControlPlugin">
      <parameters>/mnt/d/Bunker/BaseCamp/Robotics/Rovah/install/mini_model_control/share/mini_model_control/config/rover_controllers.yaml</parameters>
      <controller_manager_name>controller_manager</controller_manager_name>
      <hold_joints>true</hold_joints>
      <position_proportional_gain>0.1</position_proportional_gain>
    </plugin>
  </gazebo>
  <!-- ============================================ -->
  <!-- INTEL REALSENSE D435i RGB-D CAMERA           -->
  <!-- ============================================ -->
  <!-- Camera Link (Housing) -->
  <link name="camera_link">
    <inertial>
      <mass value="0.072"/>
      <!-- 72g actual weight -->
      <origin rpy="0 0 0" xyz="0 0 0"/>
      <inertia ixx="0.0001" ixy="0.0" ixz="0.0" iyy="0.0001" iyz="0.0" izz="0.0001"/>
    </inertial>
    <visual>
      <origin rpy="0 0 0" xyz="0 0 0"/>
      <geometry>
        <!-- Actual D435i dimensions: 90mm x 25mm x 25mm -->
        <box size="0.09 0.025 0.025"/>
      </geometry>
      <material name="camera_gray"/>
    </visual>
    <collision>
      <origin rpy="0 0 0" xyz="0 0 0"/>
      <geometry>
        <box size="0.09 0.025 0.025"/>
      </geometry>
    </collision>
  </link>
  <!-- Attach camera to front of rover, elevated for better view -->
  <joint name="camera_joint" type="fixed">
    <parent link="base_link"/>
    <child link="camera_link"/>
    <origin rpy="0 0 0" xyz="0.45 0.15 0"/>
  </joint>
  <!-- Optical frame (ROS convention: Z forward, Y down, X right) -->
  <link name="camera_optical_frame"/>
  <joint name="camera_optical_joint" type="fixed">
    <parent link="camera_link"/>
    <child link="camera_optical_frame"/>
    <origin rpy="0.0707963267948966 0.0 0.0" xyz="0 0 0"/>
  </joint>
  <!-- Camera Depth Optical Frame -->
  <link name="camera_depth_frame"/>
  <joint name="camera_depth_joint" type="fixed">
    <parent link="camera_link"/>
    <child link="camera_depth_frame"/>
    <origin rpy="0.0707963267948966 0.0 0.0" xyz="0 0 0"/>
  </joint>
  <!-- ============================================ -->
  <!-- HOKUYO UST-10LX 2D LIDAR (270° Wide Angle)   -->
  <!-- ============================================ -->
  <link name="laser_link">
    <inertial>
      <mass value="0.130"/>
      <!-- 130g typical weight -->
      <origin rpy="0 0 0" xyz="0 0 0"/>
      <inertia ixx="0.0001" ixy="0.0" ixz="0.0" iyy="0.0001" iyz="0.0" izz="0.0001"/>
    </inertial>
    <visual>
      <origin rpy="0 0 0" xyz="0 0 0"/>
      <geometry>
        <!-- Cylindrical shape: 50mm diameter, 70mm height -->
        <cylinder length="0.07" radius="0.05"/>
      </geometry>
      <material name="lidar_black"/>
    </visual>
    <collision>
      <origin rpy="0 0 0" xyz="0 0 0"/>
      <geometry>
        <cylinder length="0.07" radius="0.05"/>
      </geometry>
    </collision>
  </link>
  <!-- Mount LiDAR on top center for 360° unobstructed view -->
  <joint name="laser_joint" type="fixed">
    <parent link="base_link"/>
    <child link="laser_link"/>
    <origin rpy="1.54 0 0" xyz="0.45 0.05 0.0"/>
  </joint>
  <!-- ============================================ -->
  <!-- STANDALONE IMU (9-DOF)                       -->
  <!-- ============================================ -->
  <link name="imu_link">
    <inertial>
      <mass value="0.050"/>
      <!-- 50g typical -->
      <origin rpy="0 0 0" xyz="0 0 0"/>
      <inertia ixx="0.00001" ixy="0.0" ixz="0.0" iyy="0.00001" iyz="0.0" izz="0.00001"/>
    </inertial>
    <visual>
      <origin rpy="0 0 0" xyz="0 0 0"/>
      <geometry>
        <box size="0.03 0.03 0.01"/>
      </geometry>
      <material name="imu_blue"/>
    </visual>
    <collision>
      <origin rpy="0 0 0" xyz="0 0 0"/>
      <geometry>
        <box size="0.03 0.03 0.01"/>
      </geometry>
    </collision>
  </link>
  <!-- Place IMU at center of base_link for accurate orientation -->
  <joint name="imu_joint" type="fixed">
    <parent link="base_link"/>
    <child link="imu_link"/>
    <origin rpy="0 0 0" xyz="0.0 0.0 0.0"/>
  </joint>
  <!-- ============================================ -->
  <!-- RTK-GPS (High-Precision Positioning)         -->
  <!-- ============================================ -->
  <link name="gps_link">
    <inertial>
      <mass value="0.020"/>
      <!-- 20g typical -->
      <origin rpy="0 0 0" xyz="0 0 0"/>
      <inertia ixx="0.00001" ixy="0.0" ixz="0.0" iyy="0.00001" iyz="0.0" izz="0.00001"/>
    </inertial>
    <visual>
      <origin rpy="0 0 0" xyz="0 0 0"/>
      <geometry>
        <!-- GPS antenna: 30mm diameter, 15mm height -->
        <cylinder length="0.015" radius="0.03"/>
      </geometry>
      <material name="gps_green"/>
    </visual>
    <collision>
      <origin rpy="0 0 0" xyz="0 0 0"/>
      <geometry>
        <cylinder length="0.015" radius="0.03"/>
      </geometry>
    </collision>
  </link>
  <!-- Mount GPS at highest point for best satellite visibility -->
  <joint name="gps_joint" type="fixed">
    <parent link="base_link"/>
    <child link="gps_link"/>
    <origin rpy="1.54 0 0" xyz="0.0 0.12 0"/>
  </joint>
</robot>
